Workbook

Sheet Raw Rejection Data
B1: Job Rejections and Job Applicant System
A3: Company | B3: System | C3: System ID | D3: Return Address Name | E3: Return Address | F3: Subject Line | G3: Denial Text
A4: Impiricus | B4: Greenhouse | C4: 1 | D4: no-reply@us.greenhouse-mail.io | E4: no-reply@us.greenhouse-mail.io | F4: Thank you for your interest in Impiricus | G4: After careful review, we’ve decided to move forward with other candidates whose experience more closely aligns with our current needs.
A5: Judi Health/Capital Rx | B5: Greenhouse | C5: 1 | D5: no-reply@us.greenhouse-mail.io | E5: no-reply@us.greenhouse-mail.io | F5: Judi Health/Capital Rx | Update | G5: After reviewing your resume, we have decided to pursue other candidates that are more aligned with the qualifications of the position.
A6: SmithRx | B6: Greenhouse | C6: 1 | D6: no-reply@smithrx.com | E6: no-reply@smithrx.com | F6: Update on your application for Benefits Configuration Analyst with SmithRx | G6: After careful review, we have decided to move forward with other candidates whose experience and qualifications more closely align with the needs of this role.
A7: TechnologyAdvice | B7: Greenhouse | C7: 1 | D7: no-reply@us.greenhouse-mail.io | E7: no-reply@us.greenhouse-mail.io | F7: Update on your Application Status | G7: After careful consideration, we have decided to move forward with other candidates at this time.
A8: Navitus Health Solutions, LLC | B8: ICIMS | C8: 2 | D8: Do Not Reply | E8: navitus+email+7cgu-2b393f9b3b@talent.icims.com | F8: Thank You from Navitus Health Solutions, LLC | G8: After careful review of your application, we've decided that we will not move you forward in the hiring process.
A9: Personify Health | B9: ICIMS | C9: 2 | D9: [First Name] [Last Name] | E9: XXXX.icims.com | F9: Thank You For Your Interest! | G9: At this time, the position has been filled.
A10: AvailityLife | B10: Workday | C10: 3 | D10: Workday - AvailityLife | E10: availity@myworkday.com | F10: Client Services Technical Support Specialist I (Remote) position at Availity | G10: We had several qualified candidates apply for the position and have decided to move forward with other candidates.
A11: Crowe | B11: Workday | C11: 3 | D11: Workday @ Crowe (Do Not Reply) | E11: workday@workday.crowe.com | F11: Your Crowe Application Status - HCM Payroll Business and Systems Implementation Analyst | G11: […] we have decided to pursue other candidates at this time.
A12: OneDigital | B12: Workday | C12: 3 | D12: Workday@OneDigitial | E12: Workday@onedigital.com | F12: Thank You for Applying | G12: […] we’ve decided to move forward with other applicants that better meet the core requirements of this role.
A13: Veralto | B13: Workday | C13: 3 | D13: Veralto HR | E13: veralto@myworkday.com | F13: Application Status Update | G13: We decided to move forward with other candidates, but we thank you for giving us the opportunity to learn about your skills and accomplishments.
A14: Alight | B14: Workday | C14: 3 | D14: Alight Workday | E14: alight@myworkday.com | F14: Application Status | G14: After careful review, we regret to inform you that we have chosen to pursue other candidates whose skills, background, and education more closely align with the qualifications of the role.
A15: Aria Care Partners | B15: Paylocity | C15: 4 | D15: Aria Care Partners | E15: do-not-reply@mail.paylocity.com | F15: Your Application to Aria Care Partners | G15: We carefully reviewed a number of applications, and, though your resume was impressive, we have decided to move forward with a candidate whose qualifications are better suited to this particular role.
... A20: Rippling | B20: Rippling | C20: 8 | D20: Rippling | E20: no-reply@ats.rippling.com | F20: Thank you for applying to Rippling - Implementation Specialist, Platform | G20: While we were impressed with your qualifications, we have decided to move forward with other candidates at this time.

Sheet Stats
A1: ATS Software | B1: System ID | C1: Number of Rejections | E1: Phrase | F1: Count | H1: Count by Software
A2: ='Raw Rejection Data'!B4 -> Greenhouse | B2: ='Raw Rejection Data'!C4 -> 1 | C2: =COUNTIF('Raw Rejection Data'!B:B,A2) -> 4 | E2: Form of align | F2: ='Derived Rejection Data'!B21 -> 4 | H2: =CONCATENATE($A2," + ",$E$2) -> Greenhouse + Form of align | I2: ='Derived Rejection Data'!I$21 -> 3
A3: ='Raw Rejection Data'!B8 -> ICIMS | B3: ='Raw Rejection Data'!C8 -> 2 | C3: =COUNTIF('Raw Rejection Data'!B:B,A3) -> 2 | E3: Move | F3: ='Derived Rejection Data'!C21 -> 10 | H3: =CONCATENATE($A2," + ",$E$3) -> Greenhouse + Move | I3: ='Derived Rejection Data'!J$21 -> 3
A4: ='Raw Rejection Data'!B10 -> Workday | B4: ='Raw Rejection Data'!C10 -> 3 | C4: =COUNTIF('Raw Rejection Data'!B:B,A4) -> 5 | E4: Closer match | F4: ='Derived Rejection Data'!D21 -> 1 | H4: =CONCATENATE($A2," + ",$E$4) -> Greenhouse + Closer match | I4: ='Derived Rejection Data'!K$21 -> 0
A5: ='Raw Rejection Data'!B15 -> Paylocity | B5: ='Raw Rejection Data'!C15 -> 4 | C5: =COUNTIF('Raw Rejection Data'!B:B,A5) -> 2 | E5: better meet | F5: ='Derived Rejection Data'!E21 -> 1 | H5: =CONCATENATE($A2," + ",$E$5) -> Greenhouse + better meet | I5: ='Derived Rejection Data'!L$21 -> 0
A6: ='Raw Rejection Data'!B17 -> Ashby | B6: ='Raw Rejection Data'!C17 -> 5 | C6: =COUNTIF('Raw Rejection Data'!B:B,A6) -> 1 | E6: filled | F6: ='Derived Rejection Data'!F21 -> 2 | H6: =CONCATENATE($A2," + ",$E$6) -> Greenhouse + filled | I6: ='Derived Rejection Data'!M$21 -> 0
A7: ='Raw Rejection Data'!B18 -> JazzHr | B7: ='Raw Rejection Data'!C18 -> 6 | C7: =COUNTIF('Raw Rejection Data'!B:B,A7) -> 1 | E7: pursue other | F7: ='Derived Rejection Data'!G21 -> 3 | H7: =CONCATENATE($A2," + ",$E$7) -> Greenhouse + pursue other | I7: ='Derived Rejection Data'!N$21 -> 0
A8: ='Raw Rejection Data'!B19 -> SAP Success Factors | B8: ='Raw Rejection Data'!C19 -> 7 | C8: =COUNTIF('Raw Rejection Data'!B:B,A8) -> 1 | H8: =CONCATENATE($A3," + ",$E$2) -> ICIMS + Form of align | I8: ='Derived Rejection Data'!O$21 -> 0
A9: ='Raw Rejection Data'!B20 -> Rippling | B9: ='Raw Rejection Data'!C20 -> 8 | C9: =COUNTIF('Raw Rejection Data'!B:B,A9) -> 1 | H9: =CONCATENATE($A3," + ",$E$3) -> ICIMS + Move | I9: ='Derived Rejection Data'!P$21 -> 1
H10: =CONCATENATE($A3," + ",$E$4) -> ICIMS + Closer match | I10: ='Derived Rejection Data'!Q$21 -> 0
H11: =CONCATENATE($A3," + ",$E$5) -> ICIMS + better meet | I11: ='Derived Rejection Data'!R$21 -> 0
H12: =CONCATENATE($A3," + ",$E$6) -> ICIMS + filled | I12: ='Derived Rejection Data'!S$21 -> 1
H13: =CONCATENATE($A3," + ",$E$7) -> ICIMS + pursue other | I13: ='Derived Rejection Data'!T$21 -> 0
H14: =CONCATENATE($A4," + ",$E$2) -> Workday + Form of align | I14: ='Derived Rejection Data'!U$21 -> 1
H15: =CONCATENATE($A4," + ",$E$3) -> Workday + Move | I15: ='Derived Rejection Data'!V$21 -> 3
H16: =CONCATENATE($A4," + ",$E$4) -> Workday + Closer match | I16: ='Derived Rejection Data'!W$21 -> 0
H17: =CONCATENATE($A4," + ",$E$5) -> Workday + better meet | I17: ='Derived Rejection Data'!X$21 -> 1
H18: =CONCATENATE($A4," + ",$E$6) -> Workday + filled | I18: ='Derived Rejection Data'!Y$21 -> 0
H19: =CONCATENATE($A4," + ",$E$7) -> Workday + pursue other | I19: ='Derived Rejection Data'!Z$21 -> 2
H20: =CONCATENATE($A5," + ",$E$2) -> Paylocity + Form of align | I20: ='Derived Rejection Data'!AA$21 -> 0
H21: =CONCATENATE($A5," + ",$E$3) -> Paylocity + Move | I21: ='Derived Rejection Data'!AB$21 -> 1
H22: =CONCATENATE($A5," + ",$E$4) -> Paylocity + Closer match | I22: ='Derived Rejection Data'!AC$21 -> 1
H23: =CONCATENATE($A5," + ",$E$5) -> Paylocity + better meet | I23: ='Derived Rejection Data'!AD$21 -> 0
H24: =CONCATENATE($A5," + ",$E$7) -> Paylocity + pursue other | I24: ='Derived Rejection Data'!AE$21 -> 0
H25: =CONCATENATE($A6," + ",$E$6) -> Ashby + filled | I25: ='Derived Rejection Data'!AF$21 -> 0
H26: =CONCATENATE($A6," + ",$E$2) -> Ashby + Form of align | I26: ='Derived Rejection Data'!AG$21 -> 0
H27: =CONCATENATE($A6," + ",$E$3) -> Ashby + Move | I27: ='Derived Rejection Data'!AH$21 -> 0
H28: =CONCATENATE($A6," + ",$E$4) -> Ashby + Closer match | I28: ='Derived Rejection Data'!AI$21 -> 0
H29: =CONCATENATE($A6," + ",$E$5) -> Ashby + better meet | I29: ='Derived Rejection Data'!AJ$21 -> 0
H30: =CONCATENATE($A6," + ",$E$6) -> Ashby + filled | I30: ='Derived Rejection Data'!AK$21 -> 1
H31: =CONCATENATE($A6," + ",$E$7) -> Ashby + pursue other | I31: ='Derived Rejection Data'!AL$21 -> 0
H32: =CONCATENATE($A7," + ",$E$2) -> JazzHr + Form of align | I32: ='Derived Rejection Data'!AM$21 -> 0
H33: =CONCATENATE($A7," + ",$E$3) -> JazzHr + Move | I33: ='Derived Rejection Data'!AN$21 -> 1
H34: =CONCATENATE($A7," + ",$E$4) -> JazzHr + Closer match | I34: ='Derived Rejection Data'!AO$21 -> 0
H35: =CONCATENATE($A7," + ",$E$5) -> JazzHr + better meet | I35: ='Derived Rejection Data'!AP$21 -> 0
H36: =CONCATENATE($A7," + ",$E$6) -> JazzHr + filled | I36: ='Derived Rejection Data'!AQ$21 -> 0
H37: =CONCATENATE($A7," + ",$E$7) -> JazzHr + pursue other | I37: ='Derived Rejection Data'!AR$21 -> 0
H38: =CONCATENATE($A8," + ",$E$2) -> SAP Success Factors + Form of align | I38: ='Derived Rejection Data'!AS$21 -> 0
H39: =CONCATENATE($A8," + ",$E$3) -> SAP Success Factors + Move | I39: ='Derived Rejection Data'!AT$21 -> 0
H40: =CONCATENATE($A8," + ",$E$4) -> SAP Success Factors + Closer match | I40: ='Derived Rejection Data'!AU$21 -> 0
...

Sheet Derived Rejection Data
A1: TERM SEARCH | I1: Greenhouse | O1: ICIMS | U1: Workday | AA1: Paylocity | AG1: Ashby | AM1: JazzHr | AS1: SAP Success Factors | AY1: Rippling
A2: System | B2: "ALIGN" | C2: "MOVE" | D2: CLOSER MATCH | E2: BETTER MEET | F2: FILLED | G2: PURSUE OTHER | I2: Align | J2: Move Forward | K2: Closer Match | L2: Better Meet | M2: Filled | N2: Pursue Other | O2: Align | P2: Move Forward | Q2: Closer Match | R2: Better Meet | S2: Filled | T2: Pursue Other | U2: Align | V2: Move Forward | W2: Closer Match | X2: Better Meet | Y2: Filled | Z2: Pursue Other | AA2: Align | AB2: Move Forward | AC2: Closer Match | AD2: Better Meet | AE2: Filled | AF2: Pursue Other | AG2: Align | AH2: Move Forward | AI2: Closer Match | AJ2: Better Meet | AK2: Filled | AL2: Pursue Other | AM2: Align | AN2: Move Forward | AO2: Closer Match | AP2: Better Meet | AQ2: Filled | AR2: Pursue Other | AS2: Align | AT2: Move Forward | AU2: Closer Match | AV2: Better Meet | AW2: Filled | AX2: Pursue Other | AY2: Align | AZ2: Move Forward | BA2: Closer Match | BB2: Better Meet | BC2: Filled | BD2: Pursue Other
A3: ='Raw Rejection Data'!B4 -> Greenhouse | B3: =IF(ISNUMBER(SEARCH("align",'Raw Rejection Data'!$G4)),1,0) -> 1 | C3: =IF(ISNUMBER(SEARCH("*mov*",'Raw Rejection Data'!$G4)),1,0) -> 1 | D3: =IF(ISNUMBER(SEARCH("closer match",'Raw Rejection Data'!$G4)),1,0) -> 0 | E3: =IF(ISNUMBER(SEARCH("better meet",'Raw Rejection Data'!$G4)),1,0) -> 0 | F3: =IF(ISNUMBER(SEARCH("filled",'Raw Rejection Data'!$G4)),1,0) -> 0 | G3: =IF(ISNUMBER(SEARCH("*pursue other*",'Raw Rejection Data'!$G4)),1,0) -> 0 | I3: =IF($I$1=$A3,$B3,0) -> 1 | J3: =IF($I$1=$A3,$C3,0) -> 1 | K3: =IF($I$1=$A3,$D3,0) -> 0 | L3: =IF($I$1=$A3,$E3,0) -> 0 | M3: =IF($I$1=$A3,$F3,0) -> 0 | N3: =IF($I$1=$A3,$G3,0) -> 0 | O3: =IF($O$1=$A3,$B3,0) -> 0 | P3: =IF($O$1=$A3,$C3,0) -> 0 | Q3: =IF($O$1=$A3,$D3,0) -> 0 | R3: =IF($O$1=$A3,$E3,0) -> 0 | S3: =IF($O$1=$A3,$F3,0) -> 0 | T3: =IF($O$1=$A3,$G3,0) -> 0 | U3: =IF($U$1=$A3,$B3,0) -> 0 | V3: =IF($U$1=$A3,$C3,0) -> 0 | W3: =IF($U$1=$A3,$D3,0) -> 0 | X3: =IF($U$1=$A3,$E3,0) -> 0 | Y3: =IF($U$1=$A3,$F3,0) -> 0 | Z3: =IF($U$1=$A3,$G3,0) -> 0 | AA3: =IF($AA$1=$A3,$B3,0) -> 0 | AB3: =IF($AA$1=$A3,$C3,0) -> 0 | AC3: =IF($AA$1=$A3,$D3,0) -> 0 | AD3: =IF($AA$1=$A3,$E3,0) -> 0 | AE3: =IF($AA$1=$A3,$F3,0) -> 0 | AF3: =IF($AA$1=$A3,$G3,0) -> 0 | AG3: =IF($AG$1=$A3,$B3,0) -> 0 | AH3: =IF($AG$1=$A3,$C3,0) -> 0 | AI3: =IF($AG$1=$A3,$D3,0) -> 0 | AJ3: =IF($AG$1=$A3,$E3,0) -> 0 | AK3: =IF($AG$1=$A3,$F3,0) -> 0 | AL3: =IF($AG$1=$A3,$G3,0) -> 0 | AM3: =IF($AM$1=$A3,$B3,0) -> 0 | AN3: =IF($AM$1=$A3,$C3,0) -> 0 | AO3: =IF($AM$1=$A3,$D3,0) -> 0 | AP3: =IF($AM$1=$A3,$E3,0) -> 0 | AQ3: =IF($AM$1=$A3,$F3,0) -> 0 | AR3: =IF($AM$1=$A3,$G3,0) -> 0 | AS3: =IF($AS$1=$A3,$B3,0) -> 0 | AT3: =IF($AS$1=$A3,$C3,0) -> 0 | AU3: =IF($AS$1=$A3,$D3,0) -> 0 | AV3: =IF($AS$1=$A3,$E3,0) -> 0 | AW3: =IF($AS$1=$A3,$F3,0) -> 0 | AX3: =IF($AS$1=$A3,$G3,0) -> 0 | AY3: =IF($AY$1=$A3,$B3,0) -> 0 | AZ3: =IF($AY$1=$A3,$C3,0) -> 0 | BA3: =IF($AY$1=$A3,$D3,0) -> 0 | BB3: =IF($AY$1=$A3,$E3,0) -> 0 | BC3: =IF($AY$1=$A3,$F3,0) -> 0 | BD3: =IF($AY$1=$A3,$G3,0) -> 0
A4: ='Raw Rejection Data'!B5 -> Greenhouse | B4: =IF(ISNUMBER(SEARCH("align",'Raw Rejection Data'!$G5)),1,0) -> 1 | C4: =IF(ISNUMBER(SEARCH("*mov*",'Raw Rejection Data'!$G5)),1,0) -> 0 | D4: =IF(ISNUMBER(SEARCH("closer match",'Raw Rejection Data'!$G5)),1,0) -> 0 | E4: =IF(ISNUMBER(SEARCH("better meet",'Raw Rejection Data'!$G5)),1,0) -> 0 | F4: =IF(ISNUMBER(SEARCH("filled",'Raw Rejection Data'!$G5)),1,0) -> 0 | G4: =IF(ISNUMBER(SEARCH("*pursue other*",'Raw Rejection Data'!$G5)),1,0) -> 0 | I4: =IF($I$1=$A4,$B4,0) -> 1 | J4: =IF($I$1=$A4,$C4,0) -> 0 | K4: =IF($I$1=$A4,$D4,0) -> 0 | L4: =IF($I$1=$A4,$E4,0) -> 0 | M4: =IF($I$1=$A4,$F4,0) -> 0 | N4: =IF($I$1=$A4,$G4,0) -> 0 | O4: =IF($O$1=$A4,$B4,0) -> 0 | P4: =IF($O$1=$A4,$C4,0) -> 0 | Q4: =IF($O$1=$A4,$D4,0) -> 0 | R4: =IF($O$1=$A4,$E4,0) -> 0 | S4: =IF($O$1=$A4,$F4,0) -> 0 | T4: =IF($O$1=$A4,$G4,0) -> 0 | U4: =IF($U$1=$A4,$B4,0) -> 0 | V4: =IF($U$1=$A4,$C4,0) -> 0 | W4: =IF($U$1=$A4,$D4,0) -> 0 | X4: =IF($U$1=$A4,$E4,0) -> 0 | Y4: =IF($U$1=$A4,$F4,0) -> 0 | Z4: =IF($U$1=$A4,$G4,0) -> 0 | AA4: =IF($AA$1=$A4,$B4,0) -> 0 | AB4: =IF($AA$1=$A4,$C4,0) -> 0 | AC4: =IF($AA$1=$A4,$D4,0) -> 0 | AD4: =IF($AA$1=$A4,$E4,0) -> 0 | AE4: =IF($AA$1=$A4,$F4,0) -> 0 | AF4: =IF($AA$1=$A4,$G4,0) -> 0 | AG4: =IF($AG$1=$A4,$B4,0) -> 0 | AH4: =IF($AG$1=$A4,$C4,0) -> 0 | AI4: =IF($AG$1=$A4,$D4,0) -> 0 | AJ4: =IF($AG$1=$A4,$E4,0) -> 0 | AK4: =IF($AG$1=$A4,$F4,0) -> 0 | AL4: =IF($AG$1=$A4,$G4,0) -> 0 | AM4: =IF($AM$1=$A4,$B4,0) -> 0 | AN4: =IF($AM$1=$A4,$C4,0) -> 0 | AO4: =IF($AM$1=$A4,$D4,0) -> 0 | AP4: =IF($AM$1=$A4,$E4,0) -> 0 | AQ4: =IF($AM$1=$A4,$F4,0) -> 0 | AR4: =IF($AM$1=$A4,$G4,0) -> 0 | AS4: =IF($AS$1=$A4,$B4,0) -> 0 | AT4: =IF($AS$1=$A4,$C4,0) -> 0 | AU4: =IF($AS$1=$A4,$D4,0) -> 0 | AV4: =IF($AS$1=$A4,$E4,0) -> 0 | AW4: =IF($AS$1=$A4,$F4,0) -> 0 | AX4: =IF($AS$1=$A4,$G4,0) -> 0 | AY4: =IF($AY$1=$A4,$B4,0) -> 0 | AZ4: =IF($AY$1=$A4,$C4,0) -> 0 | BA4: =IF($AY$1=$A4,$D4,0) -> 0 | BB4: =IF($AY$1=$A4,$E4,0) -> 0 | BC4: =IF($AY$1=$A4,$F4,0) -> 0 | BD4: =IF($AY$1=$A4,$G4,0) -> 0
A5: ='Raw Rejection Data'!B6 -> Greenhouse | B5: =IF(ISNUMBER(SEARCH("align",'Raw Rejection Data'!$G6)),1,0) -> 1 | C5: =IF(ISNUMBER(SEARCH("*mov*",'Raw Rejection Data'!$G6)),1,0) -> 1 | D5: =IF(ISNUMBER(SEARCH("closer match",'Raw Rejection Data'!$G6)),1,0) -> 0 | E5: =IF(ISNUMBER(SEARCH("better meet",'Raw Rejection Data'!$G6)),1,0) -> 0 | F5: =IF(ISNUMBER(SEARCH("filled",'Raw Rejection Data'!$G6)),1,0) -> 0 | G5: =IF(ISNUMBER(SEARCH("*pursue other*",'Raw Rejection Data'!$G6)),1,0) -> 0 | I5: =IF($I$1=$A5,$B5,0) -> 1 | J5: =IF($I$1=$A5,$C5,0) -> 1 | K5: =IF($I$1=$A5,$D5,0) -> 0 | L5: =IF($I$1=$A5,$E5,0) -> 0 | M5: =IF($I$1=$A5,$F5,0) -> 0 | N5: =IF($I$1=$A5,$G5,0) -> 0 | O5: =IF($O$1=$A5,$B5,0) -> 0 | P5: =IF($O$1=$A5,$C5,0) -> 0 | Q5: =IF($O$1=$A5,$D5,0) -> 0 | R5: =IF($O$1=$A5,$E5,0) -> 0 | S5: =IF($O$1=$A5,$F5,0) -> 0 | T5: =IF($O$1=$A5,$G5,0) -> 0 | U5: =IF($U$1=$A5,$B5,0) -> 0 | V5: =IF($U$1=$A5,$C5,0) -> 0 | W5: =IF($U$1=$A5,$D5,0) -> 0 | X5: =IF($U$1=$A5,$E5,0) -> 0 | Y5: =IF($U$1=$A5,$F5,0) -> 0 | Z5: =IF($U$1=$A5,$G5,0) -> 0 | AA5: =IF($AA$1=$A5,$B5,0) -> 0 | AB5: =IF($AA$1=$A5,$C5,0) -> 0 | AC5: =IF($AA$1=$A5,$D5,0) -> 0 | AD5: =IF($AA$1=$A5,$E5,0) -> 0 | AE5: =IF($AA$1=$A5,$F5,0) -> 0 | AF5: =IF($AA$1=$A5,$G5,0) -> 0 | AG5: =IF($AG$1=$A5,$B5,0) -> 0 | AH5: =IF($AG$1=$A5,$C5,0) -> 0 | AI5: =IF($AG$1=$A5,$D5,0) -> 0 | AJ5: =IF($AG$1=$A5,$E5,0) -> 0 | AK5: =IF($AG$1=$A5,$F5,0) -> 0 | AL5: =IF($AG$1=$A5,$G5,0) -> 0 | AM5: =IF($AM$1=$A5,$B5,0) -> 0 | AN5: =IF($AM$1=$A5,$C5,0) -> 0 | AO5: =IF($AM$1=$A5,$D5,0) -> 0 | AP5: =IF($AM$1=$A5,$E5,0) -> 0 | AQ5: =IF($AM$1=$A5,$F5,0) -> 0 | AR5: =IF($AM$1=$A5,$G5,0) -> 0 | AS5: =IF($AS$1=$A5,$B5,0) -> 0 | AT5: =IF($AS$1=$A5,$C5,0) -> 0 | AU5: =IF($AS$1=$A5,$D5,0) -> 0 | AV5: =IF($AS$1=$A5,$E5,0) -> 0 | AW5: =IF($AS$1=$A5,$F5,0) -> 0 | AX5: =IF($AS$1=$A5,$G5,0) -> 0 | AY5: =IF($AY$1=$A5,$B5,0) -> 0 | AZ5: =IF($AY$1=$A5,$C5,0) -> 0 | BA5: =IF($AY$1=$A5,$D5,0) -> 0 | BB5: =IF($AY$1=$A5,$E5,0) -> 0 | BC5: =IF($AY$1=$A5,$F5,0) -> 0 | BD5: =IF($AY$1=$A5,$G5,0) -> 0
A6: ='Raw Rejection Data'!B7 -> Greenhouse | B6: =IF(ISNUMBER(SEARCH("align",'Raw Rejection Data'!$G7)),1,0) -> 0 | C6: =IF(ISNUMBER(SEARCH("*mov*",'Raw Rejection Data'!$G7)),1,0) -> 1 | D6: =IF(ISNUMBER(SEARCH("closer match",'Raw Rejection Data'!$G7)),1,0) -> 0 | E6: =IF(ISNUMBER(SEARCH("better meet",'Raw Rejection Data'!$G7)),1,0) -> 0 | F6: =IF(ISNUMBER(SEARCH("filled",'Raw Rejection Data'!$G7)),1,0) -> 0 | G6: =IF(ISNUMBER(SEARCH("*pursue other*",'Raw Rejection Data'!$G7)),1,0) -> 0 | I6: =IF($I$1=$A6,$B6,0) -> 0 | J6: =IF($I$1=$A6,$C6,0) -> 1 | K6: =IF($I$1=$A6,$D6,0) -> 0 | L6: =IF($I$1=$A6,$E6,0) -> 0 | M6: =IF($I$1=$A6,$F6,0) -> 0 | N6: =IF($I$1=$A6,$G6,0) -> 0 | O6: =IF($O$1=$A6,$B6,0) -> 0 | P6: =IF($O$1=$A6,$C6,0) -> 0 | Q6: =IF($O$1=$A6,$D6,0) -> 0 | R6: =IF($O$1=$A6,$E6,0) -> 0 | S6: =IF($O$1=$A6,$F6,0) -> 0 | T6: =IF($O$1=$A6,$G6,0) -> 0 | U6: =IF($U$1=$A6,$B6,0) -> 0 | V6: =IF($U$1=$A6,$C6,0) -> 0 | W6: =IF($U$1=$A6,$D6,0) -> 0 | X6: =IF($U$1=$A6,$E6,0) -> 0 | Y6: =IF($U$1=$A6,$F6,0) -> 0 | Z6: =IF($U$1=$A6,$G6,0) -> 0 | AA6: =IF($AA$1=$A6,$B6,0) -> 0 | AB6: =IF($AA$1=$A6,$C6,0) -> 0 | AC6: =IF($AA$1=$A6,$D6,0) -> 0 | AD6: =IF($AA$1=$A6,$E6,0) -> 0 | AE6: =IF($AA$1=$A6,$F6,0) -> 0 | AF6: =IF($AA$1=$A6,$G6,0) -> 0 | AG6: =IF($AG$1=$A6,$B6,0) -> 0 | AH6: =IF($AG$1=$A6,$C6,0) -> 0 | AI6: =IF($AG$1=$A6,$D6,0) -> 0 | AJ6: =IF($AG$1=$A6,$E6,0) -> 0 | AK6: =IF($AG$1=$A6,$F6,0) -> 0 | AL6: =IF($AG$1=$A6,$G6,0) -> 0 | AM6: =IF($AM$1=$A6,$B6,0) -> 0 | AN6: =IF($AM$1=$A6,$C6,0) -> 0 | AO6: =IF($AM$1=$A6,$D6,0) -> 0 | AP6: =IF($AM$1=$A6,$E6,0) -> 0 | AQ6: =IF($AM$1=$A6,$F6,0) -> 0 | AR6: =IF($AM$1=$A6,$G6,0) -> 0 | AS6: =IF($AS$1=$A6,$B6,0) -> 0 | AT6: =IF($AS$1=$A6,$C6,0) -> 0 | AU6: =IF($AS$1=$A6,$D6,0) -> 0 | AV6: =IF($AS$1=$A6,$E6,0) -> 0 | AW6: =IF($AS$1=$A6,$F6,0) -> 0 | AX6: =IF($AS$1=$A6,$G6,0) -> 0 | AY6: =IF($AY$1=$A6,$B6,0) -> 0 | AZ6: =IF($AY$1=$A6,$C6,0) -> 0 | BA6: =IF($AY$1=$A6,$D6,0) -> 0 | BB6: =IF($AY$1=$A6,$E6,0) -> 0 | BC6: =IF($AY$1=$A6,$F6,0) -> 0 | BD6: =IF($AY$1=$A6,$G6,0) -> 0
A7: ='Raw Rejection Data'!B8 -> ICIMS | B7: =IF(ISNUMBER(SEARCH("align",'Raw Rejection Data'!$G8)),1,0) -> 0 | C7: =IF(ISNUMBER(SEARCH("*mov*",'Raw Rejection Data'!$G8)),1,0) -> 1 | D7: =IF(ISNUMBER(SEARCH("closer match",'Raw Rejection Data'!$G8)),1,0) -> 0 | E7: =IF(ISNUMBER(SEARCH("better meet",'Raw Rejection Data'!$G8)),1,0) -> 0 | F7: =IF(ISNUMBER(SEARCH("filled",'Raw Rejection Data'!$G8)),1,0) -> 0 | G7: =IF(ISNUMBER(SEARCH("*pursue other*",'Raw Rejection Data'!$G8)),1,0) -> 0 | I7: =IF($I$1=$A7,$B7,0) -> 0 | J7: =IF($I$1=$A7,$C7,0) -> 0 | K7: =IF($I$1=$A7,$D7,0) -> 0 | L7: =IF($I$1=$A7,$E7,0) -> 0 | M7: =IF($I$1=$A7,$F7,0) -> 0 | N7: =IF($I$1=$A7,$G7,0) -> 0 | O7: =IF($O$1=$A7,$B7,0) -> 0 | P7: =IF($O$1=$A7,$C7,0) -> 1 | Q7: =IF($O$1=$A7,$D7,0) -> 0 | R7: =IF($O$1=$A7,$E7,0) -> 0 | S7: =IF($O$1=$A7,$F7,0) -> 0 | T7: =IF($O$1=$A7,$G7,0) -> 0 | U7: =IF($U$1=$A7,$B7,0) -> 0 | V7: =IF($U$1=$A7,$C7,0) -> 0 | W7: =IF($U$1=$A7,$D7,0) -> 0 | X7: =IF($U$1=$A7,$E7,0) -> 0 | Y7: =IF($U$1=$A7,$F7,0) -> 0 | Z7: =IF($U$1=$A7,$G7,0) -> 0 | AA7: =IF($AA$1=$A7,$B7,0) -> 0 | AB7: =IF($AA$1=$A7,$C7,0) -> 0 | AC7: =IF($AA$1=$A7,$D7,0) -> 0 | AD7: =IF($AA$1=$A7,$E7,0) -> 0 | AE7: =IF($AA$1=$A7,$F7,0) -> 0 | AF7: =IF($AA$1=$A7,$G7,0) -> 0 | AG7: =IF($AG$1=$A7,$B7,0) -> 0 | AH7: =IF($AG$1=$A7,$C7,0) -> 0 | AI7: =IF($AG$1=$A7,$D7,0) -> 0 | AJ7: =IF($AG$1=$A7,$E7,0) -> 0 | AK7: =IF($AG$1=$A7,$F7,0) -> 0 | AL7: =IF($AG$1=$A7,$G7,0) -> 0 | AM7: =IF($AM$1=$A7,$B7,0) -> 0 | AN7: =IF($AM$1=$A7,$C7,0) -> 0 | AO7: =IF($AM$1=$A7,$D7,0) -> 0 | AP7: =IF($AM$1=$A7,$E7,0) -> 0 | AQ7: =IF($AM$1=$A7,$F7,0) -> 0 | AR7: =IF($AM$1=$A7,$G7,0) -> 0 | AS7: =IF($AS$1=$A7,$B7,0) -> 0 | AT7: =IF($AS$1=$A7,$C7,0) -> 0 | AU7: =IF($AS$1=$A7,$D7,0) -> 0 | AV7: =IF($AS$1=$A7,$E7,0) -> 0 | AW7: =IF($AS$1=$A7,$F7,0) -> 0 | AX7: =IF($AS$1=$A7,$G7,0) -> 0 | AY7: =IF($AY$1=$A7,$B7,0) -> 0 | AZ7: =IF($AY$1=$A7,$C7,0) -> 0 | BA7: =IF($AY$1=$A7,$D7,0) -> 0 | BB7: =IF($AY$1=$A7,$E7,0) -> 0 | BC7: =IF($AY$1=$A7,$F7,0) -> 0 | BD7: =IF($AY$1=$A7,$G7,0) -> 0
A8: ='Raw Rejection Data'!B9 -> ICIMS | B8: =IF(ISNUMBER(SEARCH("align",'Raw Rejection Data'!$G9)),1,0) -> 0 | C8: =IF(ISNUMBER(SEARCH("*mov*",'Raw Rejection Data'!$G9)),1,0) -> 0 | D8: =IF(ISNUMBER(SEARCH("closer match",'Raw Rejection Data'!$G9)),1,0) -> 0 | E8: =IF(ISNUMBER(SEARCH("better meet",'Raw Rejection Data'!$G9)),1,0) -> 0 | F8: =IF(ISNUMBER(SEARCH("filled",'Raw Rejection Data'!$G9)),1,0) -> 1 | G8: =IF(ISNUMBER(SEARCH("*pursue other*",'Raw Rejection Data'!$G9)),1,0) -> 0 | I8: =IF($I$1=$A8,$B8,0) -> 0 | J8: =IF($I$1=$A8,$C8,0) -> 0 | K8: =IF($I$1=$A8,$D8,0) -> 0 | L8: =IF($I$1=$A8,$E8,0) -> 0 | M8: =IF($I$1=$A8,$F8,0) -> 0 | N8: =IF($I$1=$A8,$G8,0) -> 0 | O8: =IF($O$1=$A8,$B8,0) -> 0 | P8: =IF($O$1=$A8,$C8,0) -> 0 | Q8: =IF($O$1=$A8,$D8,0) -> 0 | R8: =IF($O$1=$A8,$E8,0) -> 0 | S8: =IF($O$1=$A8,$F8,0) -> 1 | T8: =IF($O$1=$A8,$G8,0) -> 0 | U8: =IF($U$1=$A8,$B8,0) -> 0 | V8: =IF($U$1=$A8,$C8,0) -> 0 | W8: =IF($U$1=$A8,$D8,0) -> 0 | X8: =IF($U$1=$A8,$E8,0) -> 0 | Y8: =IF($U$1=$A8,$F8,0) -> 0 | Z8: =IF($U$1=$A8,$G8,0) -> 0 | AA8: =IF($AA$1=$A8,$B8,0) -> 0 | AB8: =IF($AA$1=$A8,$C8,0) -> 0 | AC8: =IF($AA$1=$A8,$D8,0) -> 0 | AD8: =IF($AA$1=$A8,$E8,0) -> 0 | AE8: =IF($AA$1=$A8,$F8,0) -> 0 | AF8: =IF($AA$1=$A8,$G8,0) -> 0 | AG8: =IF($AG$1=$A8,$B8,0) -> 0 | AH8: =IF($AG$1=$A8,$C8,0) -> 0 | AI8: =IF($AG$1=$A8,$D8,0) -> 0 | AJ8: =IF($AG$1=$A8,$E8,0) -> 0 | AK8: =IF($AG$1=$A8,$F8,0) -> 0 | AL8: =IF($AG$1=$A8,$G8,0) -> 0 | AM8: =IF($AM$1=$A8,$B8,0) -> 0 | AN8: =IF($AM$1=$A8,$C8,0) -> 0 | AO8: =IF($AM$1=$A8,$D8,0) -> 0 | AP8: =IF($AM$1=$A8,$E8,0) -> 0 | AQ8: =IF($AM$1=$A8,$F8,0) -> 0 | AR8: =IF($AM$1=$A8,$G8,0) -> 0 | AS8: =IF($AS$1=$A8,$B8,0) -> 0 | AT8: =IF($AS$1=$A8,$C8,0) -> 0 | AU8: =IF($AS$1=$A8,$D8,0) -> 0 | AV8: =IF($AS$1=$A8,$E8,0) -> 0 | AW8: =IF($AS$1=$A8,$F8,0) -> 0 | AX8: =IF($AS$1=$A8,$G8,0) -> 0 | AY8: =IF($AY$1=$A8,$B8,0) -> 0 | AZ8: =IF($AY$1=$A8,$C8,0) -> 0 | BA8: =IF($AY$1=$A8,$D8,0) -> 0 | BB8: =IF($AY$1=$A8,$E8,0) -> 0 | BC8: =IF($AY$1=$A8,$F8,0) -> 0 | BD8: =IF($AY$1=$A8,$G8,0) -> 0
A9: ='Raw Rejection Data'!B10 -> Workday | B9: =IF(ISNUMBER(SEARCH("align",'Raw Rejection Data'!$G10)),1,0) -> 0 | C9: =IF(ISNUMBER(SEARCH("*mov*",'Raw Rejection Data'!$G10)),1,0) -> 1 | D9: =IF(ISNUMBER(SEARCH("closer match",'Raw Rejection Data'!$G10)),1,0) -> 0 | E9: =IF(ISNUMBER(SEARCH("better meet",'Raw Rejection Data'!$G10)),1,0) -> 0 | F9: =IF(ISNUMBER(SEARCH("filled",'Raw Rejection Data'!$G10)),1,0) -> 0 | G9: =IF(ISNUMBER(SEARCH("*pursue other*",'Raw Rejection Data'!$G10)),1,0) -> 0 | I9: =IF($I$1=$A9,$B9,0) -> 0 | J9: =IF($I$1=$A9,$C9,0) -> 0 | K9: =IF($I$1=$A9,$D9,0) -> 0 | L9: =IF($I$1=$A9,$E9,0) -> 0 | M9: =IF($I$1=$A9,$F9,0) -> 0 | N9: =IF($I$1=$A9,$G9,0) -> 0 | O9: =IF($O$1=$A9,$B9,0) -> 0 | P9: =IF($O$1=$A9,$C9,0) -> 0 | Q9: =IF($O$1=$A9,$D9,0) -> 0 | R9: =IF($O$1=$A9,$E9,0) -> 0 | S9: =IF($O$1=$A9,$F9,0) -> 0 | T9: =IF($O$1=$A9,$G9,0) -> 0 | U9: =IF($U$1=$A9,$B9,0) -> 0 | V9: =IF($U$1=$A9,$C9,0) -> 1 | W9: =IF($U$1=$A9,$D9,0) -> 0 | X9: =IF($U$1=$A9,$E9,0) -> 0 | Y9: =IF($U$1=$A9,$F9,0) -> 0 | Z9: =IF($U$1=$A9,$G9,0) -> 0 | AA9: =IF($AA$1=$A9,$B9,0) -> 0 | AB9: =IF($AA$1=$A9,$C9,0) -> 0 | AC9: =IF($AA$1=$A9,$D9,0) -> 0 | AD9: =IF($AA$1=$A9,$E9,0) -> 0 | AE9: =IF($AA$1=$A9,$F9,0) -> 0 | AF9: =IF($AA$1=$A9,$G9,0) -> 0 | AG9: =IF($AG$1=$A9,$B9,0) -> 0 | AH9: =IF($AG$1=$A9,$C9,0) -> 0 | AI9: =IF($AG$1=$A9,$D9,0) -> 0 | AJ9: =IF($AG$1=$A9,$E9,0) -> 0 | AK9: =IF($AG$1=$A9,$F9,0) -> 0 | AL9: =IF($AG$1=$A9,$G9,0) -> 0 | AM9: =IF($AM$1=$A9,$B9,0) -> 0 | AN9: =IF($AM$1=$A9,$C9,0) -> 0 | AO9: =IF($AM$1=$A9,$D9,0) -> 0 | AP9: =IF($AM$1=$A9,$E9,0) -> 0 | AQ9: =IF($AM$1=$A9,$F9,0) -> 0 | AR9: =IF($AM$1=$A9,$G9,0) -> 0 | AS9: =IF($AS$1=$A9,$B9,0) -> 0 | AT9: =IF($AS$1=$A9,$C9,0) -> 0 | AU9: =IF($AS$1=$A9,$D9,0) -> 0 | AV9: =IF($AS$1=$A9,$E9,0) -> 0 | AW9: =IF($AS$1=$A9,$F9,0) -> 0 | AX9: =IF($AS$1=$A9,$G9,0) -> 0 | AY9: =IF($AY$1=$A9,$B9,0) -> 0 | AZ9: =IF($AY$1=$A9,$C9,0) -> 0 | BA9: =IF($AY$1=$A9,$D9,0) -> 0 | BB9: =IF($AY$1=$A9,$E9,0) -> 0 | BC9: =IF($AY$1=$A9,$F9,0) -> 0 | BD9: =IF($AY$1=$A9,$G9,0) -> 0
A10: ='Raw Rejection Data'!B11 -> Workday | B10: =IF(ISNUMBER(SEARCH("align",'Raw Rejection Data'!$G11)),1,0) -> 0 | C10: =IF(ISNUMBER(SEARCH("*mov*",'Raw Rejection Data'!$G11)),1,0) -> 0 | D10: =IF(ISNUMBER(SEARCH("closer match",'Raw Rejection Data'!$G11)),1,0) -> 0 | E10: =IF(ISNUMBER(SEARCH("better meet",'Raw Rejection Data'!$G11)),1,0) -> 0 | F10: =IF(ISNUMBER(SEARCH("filled",'Raw Rejection Data'!$G11)),1,0) -> 0 | G10: =IF(ISNUMBER(SEARCH("*pursue other*",'Raw Rejection Data'!$G11)),1,0) -> 1 | I10: =IF($I$1=$A10,$B10,0) -> 0 | J10: =IF($I$1=$A10,$C10,0) -> 0 | K10: =IF($I$1=$A10,$D10,0) -> 0 | L10: =IF($I$1=$A10,$E10,0) -> 0 | M10: =IF($I$1=$A10,$F10,0) -> 0 | N10: =IF($I$1=$A10,$G10,0) -> 0 | O10: =IF($O$1=$A10,$B10,0) -> 0 | P10: =IF($O$1=$A10,$C10,0) -> 0 | Q10: =IF($O$1=$A10,$D10,0) -> 0 | R10: =IF($O$1=$A10,$E10,0) -> 0 | S10: =IF($O$1=$A10,$F10,0) -> 0 | T10: =IF($O$1=$A10,$G10,0) -> 0 | U10: =IF($U$1=$A10,$B10,0) -> 0 | V10: =IF($U$1=$A10,$C10,0) -> 0 | W10: =IF($U$1=$A10,$D10,0) -> 0 | X10: =IF($U$1=$A10,$E10,0) -> 0 | Y10: =IF($U$1=$A10,$F10,0) -> 0 | Z10: =IF($U$1=$A10,$G10,0) -> 1 | AA10: =IF($AA$1=$A10,$B10,0) -> 0 | AB10: =IF($AA$1=$A10,$C10,0) -> 0 | AC10: =IF($AA$1=$A10,$D10,0) -> 0 | AD10: =IF($AA$1=$A10,$E10,0) -> 0 | AE10: =IF($AA$1=$A10,$F10,0) -> 0 | AF10: =IF($AA$1=$A10,$G10,0) -> 0 | AG10: =IF($AG$1=$A10,$B10,0) -> 0 | AH10: =IF($AG$1=$A10,$C10,0) -> 0 | AI10: =IF($AG$1=$A10,$D10,0) -> 0 | AJ10: =IF($AG$1=$A10,$E10,0) -> 0 | AK10: =IF($AG$1=$A10,$F10,0) -> 0 | AL10: =IF($AG$1=$A10,$G10,0) -> 0 | AM10: =IF($AM$1=$A10,$B10,0) -> 0 | AN10: =IF($AM$1=$A10,$C10,0) -> 0 | AO10: =IF($AM$1=$A10,$D10,0) -> 0 | AP10: =IF($AM$1=$A10,$E10,0) -> 0 | AQ10: =IF($AM$1=$A10,$F10,0) -> 0 | AR10: =IF($AM$1=$A10,$G10,0) -> 0 | AS10: =IF($AS$1=$A10,$B10,0) -> 0 | AT10: =IF($AS$1=$A10,$C10,0) -> 0 | AU10: =IF($AS$1=$A10,$D10,0) -> 0 | AV10: =IF($AS$1=$A10,$E10,0) -> 0 | AW10: =IF($AS$1=$A10,$F10,0) -> 0 | AX10: =IF($AS$1=$A10,$G10,0) -> 0 | AY10: =IF($AY$1=$A10,$B10,0) -> 0 | AZ10: =IF($AY$1=$A10,$C10,0) -> 0 | BA10: =IF($AY$1=$A10,$D10,0) -> 0 | BB10: =IF($AY$1=$A10,$E10,0) -> 0 | BC10: =IF($AY$1=$A10,$F10,0) -> 0 | BD10: =IF($AY$1=$A10,$G10,0) -> 0
A11: ='Raw Rejection Data'!B12 -> Workday | B11: =IF(ISNUMBER(SEARCH("align",'Raw Rejection Data'!$G12)),1,0) -> 0 | C11: =IF(ISNUMBER(SEARCH("*mov*",'Raw Rejection Data'!$G12)),1,0) -> 1 | D11: =IF(ISNUMBER(SEARCH("closer match",'Raw Rejection Data'!$G12)),1,0) -> 0 | E11: =IF(ISNUMBER(SEARCH("better meet",'Raw Rejection Data'!$G12)),1,0) -> 1 | F11: =IF(ISNUMBER(SEARCH("filled",'Raw Rejection Data'!$G12)),1,0) -> 0 | G11: =IF(ISNUMBER(SEARCH("*pursue other*",'Raw Rejection Data'!$G12)),1,0) -> 0 | I11: =IF($I$1=$A11,$B11,0) -> 0 | J11: =IF($I$1=$A11,$C11,0) -> 0 | K11: =IF($I$1=$A11,$D11,0) -> 0 | L11: =IF($I$1=$A11,$E11,0) -> 0 | M11: =IF($I$1=$A11,$F11,0) -> 0 | N11: =IF($I$1=$A11,$G11,0) -> 0 | O11: =IF($O$1=$A11,$B11,0) -> 0 | P11: =IF($O$1=$A11,$C11,0) -> 0 | Q11: =IF($O$1=$A11,$D11,0) -> 0 | R11: =IF($O$1=$A11,$E11,0) -> 0 | S11: =IF($O$1=$A11,$F11,0) -> 0 | T11: =IF($O$1=$A11,$G11,0) -> 0 | U11: =IF($U$1=$A11,$B11,0) -> 0 | V11: =IF($U$1=$A11,$C11,0) -> 1 | W11: =IF($U$1=$A11,$D11,0) -> 0 | X11: =IF($U$1=$A11,$E11,0) -> 1 | Y11: =IF($U$1=$A11,$F11,0) -> 0 | Z11: =IF($U$1=$A11,$G11,0) -> 0 | AA11: =IF($AA$1=$A11,$B11,0) -> 0 | AB11: =IF($AA$1=$A11,$C11,0) -> 0 | AC11: =IF($AA$1=$A11,$D11,0) -> 0 | AD11: =IF($AA$1=$A11,$E11,0) -> 0 | AE11: =IF($AA$1=$A11,$F11,0) -> 0 | AF11: =IF($AA$1=$A11,$G11,0) -> 0 | AG11: =IF($AG$1=$A11,$B11,0) -> 0 | AH11: =IF($AG$1=$A11,$C11,0) -> 0 | AI11: =IF($AG$1=$A11,$D11,0) -> 0 | AJ11: =IF($AG$1=$A11,$E11,0) -> 0 | AK11: =IF($AG$1=$A11,$F11,0) -> 0 | AL11: =IF($AG$1=$A11,$G11,0) -> 0 | AM11: =IF($AM$1=$A11,$B11,0) -> 0 | AN11: =IF($AM$1=$A11,$C11,0) -> 0 | AO11: =IF($AM$1=$A11,$D11,0) -> 0 | AP11: =IF($AM$1=$A11,$E11,0) -> 0 | AQ11: =IF($AM$1=$A11,$F11,0) -> 0 | AR11: =IF($AM$1=$A11,$G11,0) -> 0 | AS11: =IF($AS$1=$A11,$B11,0) -> 0 | AT11: =IF($AS$1=$A11,$C11,0) -> 0 | AU11: =IF($AS$1=$A11,$D11,0) -> 0 | AV11: =IF($AS$1=$A11,$E11,0) -> 0 | AW11: =IF($AS$1=$A11,$F11,0) -> 0 | AX11: =IF($AS$1=$A11,$G11,0) -> 0 | AY11: =IF($AY$1=$A11,$B11,0) -> 0 | AZ11: =IF($AY$1=$A11,$C11,0) -> 0 | BA11: =IF($AY$1=$A11,$D11,0) -> 0 | BB11: =IF($AY$1=$A11,$E11,0) -> 0 | BC11: =IF($AY$1=$A11,$F11,0) -> 0 | BD11: =IF($AY$1=$A11,$G11,0) -> 0
A12: ='Raw Rejection Data'!B13 -> Workday | B12: =IF(ISNUMBER(SEARCH("align",'Raw Rejection Data'!$G13)),1,0) -> 0 | C12: =IF(ISNUMBER(SEARCH("*mov*",'Raw Rejection Data'!$G13)),1,0) -> 1 | D12: =IF(ISNUMBER(SEARCH("closer match",'Raw Rejection Data'!$G13)),1,0) -> 0 | E12: =IF(ISNUMBER(SEARCH("better meet",'Raw Rejection Data'!$G13)),1,0) -> 0 | F12: =IF(ISNUMBER(SEARCH("filled",'Raw Rejection Data'!$G13)),1,0) -> 0 | G12: =IF(ISNUMBER(SEARCH("*pursue other*",'Raw Rejection Data'!$G13)),1,0) -> 0 | I12: =IF($I$1=$A12,$B12,0) -> 0 | J12: =IF($I$1=$A12,$C12,0) -> 0 | K12: =IF($I$1=$A12,$D12,0) -> 0 | L12: =IF($I$1=$A12,$E12,0) -> 0 | M12: =IF($I$1=$A12,$F12,0) -> 0 | N12: =IF($I$1=$A12,$G12,0) -> 0 | O12: =IF($O$1=$A12,$B12,0) -> 0 | P12: =IF($O$1=$A12,$C12,0) -> 0 | Q12: =IF($O$1=$A12,$D12,0) -> 0 | R12: =IF($O$1=$A12,$E12,0) -> 0 | S12: =IF($O$1=$A12,$F12,0) -> 0 | T12: =IF($O$1=$A12,$G12,0) -> 0 | U12: =IF($U$1=$A12,$B12,0) -> 0 | V12: =IF($U$1=$A12,$C12,0) -> 1 | W12: =IF($U$1=$A12,$D12,0) -> 0 | X12: =IF($U$1=$A12,$E12,0) -> 0 | Y12: =IF($U$1=$A12,$F12,0) -> 0 | Z12: =IF($U$1=$A12,$G12,0) -> 0 | AA12: =IF($AA$1=$A12,$B12,0) -> 0 | AB12: =IF($AA$1=$A12,$C12,0) -> 0 | AC12: =IF($AA$1=$A12,$D12,0) -> 0 | AD12: =IF($AA$1=$A12,$E12,0) -> 0 | AE12: =IF($AA$1=$A12,$F12,0) -> 0 | AF12: =IF($AA$1=$A12,$G12,0) -> 0 | AG12: =IF($AG$1=$A12,$B12,0) -> 0 | AH12: =IF($AG$1=$A12,$C12,0) -> 0 | AI12: =IF($AG$1=$A12,$D12,0) -> 0 | AJ12: =IF($AG$1=$A12,$E12,0) -> 0 | AK12: =IF($AG$1=$A12,$F12,0) -> 0 | AL12: =IF($AG$1=$A12,$G12,0) -> 0 | AM12: =IF($AM$1=$A12,$B12,0) -> 0 | AN12: =IF($AM$1=$A12,$C12,0) -> 0 | AO12: =IF($AM$1=$A12,$D12,0) -> 0 | AP12: =IF($AM$1=$A12,$E12,0) -> 0 | AQ12: =IF($AM$1=$A12,$F12,0) -> 0 | AR12: =IF($AM$1=$A12,$G12,0) -> 0 | AS12: =IF($AS$1=$A12,$B12,0) -> 0 | AT12: =IF($AS$1=$A12,$C12,0) -> 0 | AU12: =IF($AS$1=$A12,$D12,0) -> 0 | AV12: =IF($AS$1=$A12,$E12,0) -> 0 | AW12: =IF($AS$1=$A12,$F12,0) -> 0 | AX12: =IF($AS$1=$A12,$G12,0) -> 0 | AY12: =IF($AY$1=$A12,$B12,0) -> 0 | AZ12: =IF($AY$1=$A12,$C12,0) -> 0 | BA12: =IF($AY$1=$A12,$D12,0) -> 0 | BB12: =IF($AY$1=$A12,$E12,0) -> 0 | BC12: =IF($AY$1=$A12,$F12,0) -> 0 | BD12: =IF($AY$1=$A12,$G12,0) -> 0
A13: ='Raw Rejection Data'!B14 -> Workday | B13: =IF(ISNUMBER(SEARCH("align",'Raw Rejection Data'!$G14)),1,0) -> 1 | C13: =IF(ISNUMBER(SEARCH("*mov*",'Raw Rejection Data'!$G14)),1,0) -> 0 | D13: =IF(ISNUMBER(SEARCH("closer match",'Raw Rejection Data'!$G14)),1,0) -> 0 | E13: =IF(ISNUMBER(SEARCH("better meet",'Raw Rejection Data'!$G14)),1,0) -> 0 | F13: =IF(ISNUMBER(SEARCH("filled",'Raw Rejection Data'!$G14)),1,0) -> 0 | G13: =IF(ISNUMBER(SEARCH("*pursue other*",'Raw Rejection Data'!$G14)),1,0) -> 1 | I13: =IF($I$1=$A13,$B13,0) -> 0 | J13: =IF($I$1=$A13,$C13,0) -> 0 | K13: =IF($I$1=$A13,$D13,0) -> 0 | L13: =IF($I$1=$A13,$E13,0) -> 0 | M13: =IF($I$1=$A13,$F13,0) -> 0 | N13: =IF($I$1=$A13,$G13,0) -> 0 | O13: =IF($O$1=$A13,$B13,0) -> 0 | P13: =IF($O$1=$A13,$C13,0) -> 0 | Q13: =IF($O$1=$A13,$D13,0) -> 0 | R13: =IF($O$1=$A13,$E13,0) -> 0 | S13: =IF($O$1=$A13,$F13,0) -> 0 | T13: =IF($O$1=$A13,$G13,0) -> 0 | U13: =IF($U$1=$A13,$B13,0) -> 1 | V13: =IF($U$1=$A13,$C13,0) -> 0 | W13: =IF($U$1=$A13,$D13,0) -> 0 | X13: =IF($U$1=$A13,$E13,0) -> 0 | Y13: =IF($U$1=$A13,$F13,0) -> 0 | Z13: =IF($U$1=$A13,$G13,0) -> 1 | AA13: =IF($AA$1=$A13,$B13,0) -> 0 | AB13: =IF($AA$1=$A13,$C13,0) -> 0 | AC13: =IF($AA$1=$A13,$D13,0) -> 0 | AD13: =IF($AA$1=$A13,$E13,0) -> 0 | AE13: =IF($AA$1=$A13,$F13,0) -> 0 | AF13: =IF($AA$1=$A13,$G13,0) -> 0 | AG13: =IF($AG$1=$A13,$B13,0) -> 0 | AH13: =IF($AG$1=$A13,$C13,0) -> 0 | AI13: =IF($AG$1=$A13,$D13,0) -> 0 | AJ13: =IF($AG$1=$A13,$E13,0) -> 0 | AK13: =IF($AG$1=$A13,$F13,0) -> 0 | AL13: =IF($AG$1=$A13,$G13,0) -> 0 | AM13: =IF($AM$1=$A13,$B13,0) -> 0 | AN13: =IF($AM$1=$A13,$C13,0) -> 0 | AO13: =IF($AM$1=$A13,$D13,0) -> 0 | AP13: =IF($AM$1=$A13,$E13,0) -> 0 | AQ13: =IF($AM$1=$A13,$F13,0) -> 0 | AR13: =IF($AM$1=$A13,$G13,0) -> 0 | AS13: =IF($AS$1=$A13,$B13,0) -> 0 | AT13: =IF($AS$1=$A13,$C13,0) -> 0 | AU13: =IF($AS$1=$A13,$D13,0) -> 0 | AV13: =IF($AS$1=$A13,$E13,0) -> 0 | AW13: =IF($AS$1=$A13,$F13,0) -> 0 | AX13: =IF($AS$1=$A13,$G13,0) -> 0 | AY13: =IF($AY$1=$A13,$B13,0) -> 0 | AZ13: =IF($AY$1=$A13,$C13,0) -> 0 | BA13: =IF($AY$1=$A13,$D13,0) -> 0 | BB13: =IF($AY$1=$A13,$E13,0) -> 0 | BC13: =IF($AY$1=$A13,$F13,0) -> 0 | BD13: =IF($AY$1=$A13,$G13,0) -> 0
A14: ='Raw Rejection Data'!B15 -> Paylocity | B14: =IF(ISNUMBER(SEARCH("align",'Raw Rejection Data'!$G15)),1,0) -> 0 | C14: =IF(ISNUMBER(SEARCH("*mov*",'Raw Rejection Data'!$G15)),1,0) -> 1 | D14: =IF(ISNUMBER(SEARCH("closer match",'Raw Rejection Data'!$G15)),1,0) -> 0 | E14: =IF(ISNUMBER(SEARCH("better meet",'Raw Rejection Data'!$G15)),1,0) -> 0 | F14: =IF(ISNUMBER(SEARCH("filled",'Raw Rejection Data'!$G15)),1,0) -> 0 | G14: =IF(ISNUMBER(SEARCH("*pursue other*",'Raw Rejection Data'!$G15)),1,0) -> 0 | I14: =IF($I$1=$A14,$B14,0) -> 0 | J14: =IF($I$1=$A14,$C14,0) -> 0 | K14: =IF($I$1=$A14,$D14,0) -> 0 | L14: =IF($I$1=$A14,$E14,0) -> 0 | M14: =IF($I$1=$A14,$F14,0) -> 0 | N14: =IF($I$1=$A14,$G14,0) -> 0 | O14: =IF($O$1=$A14,$B14,0) -> 0 | P14: =IF($O$1=$A14,$C14,0) -> 0 | Q14: =IF($O$1=$A14,$D14,0) -> 0 | R14: =IF($O$1=$A14,$E14,0) -> 0 | S14: =IF($O$1=$A14,$F14,0) -> 0 | T14: =IF($O$1=$A14,$G14,0) -> 0 | U14: =IF($U$1=$A14,$B14,0) -> 0 | V14: =IF($U$1=$A14,$C14,0) -> 0 | W14: =IF($U$1=$A14,$D14,0) -> 0 | X14: =IF($U$1=$A14,$E14,0) -> 0 | Y14: =IF($U$1=$A14,$F14,0) -> 0 | Z14: =IF($U$1=$A14,$G14,0) -> 0 | AA14: =IF($AA$1=$A14,$B14,0) -> 0 | AB14: =IF($AA$1=$A14,$C14,0) -> 1 | AC14: =IF($AA$1=$A14,$D14,0) -> 0 | AD14: =IF($AA$1=$A14,$E14,0) -> 0 | AE14: =IF($AA$1=$A14,$F14,0) -> 0 | AF14: =IF($AA$1=$A14,$G14,0) -> 0 | AG14: =IF($AG$1=$A14,$B14,0) -> 0 | AH14: =IF($AG$1=$A14,$C14,0) -> 0 | AI14: =IF($AG$1=$A14,$D14,0) -> 0 | AJ14: =IF($AG$1=$A14,$E14,0) -> 0 | AK14: =IF($AG$1=$A14,$F14,0) -> 0 | AL14: =IF($AG$1=$A14,$G14,0) -> 0 | AM14: =IF($AM$1=$A14,$B14,0) -> 0 | AN14: =IF($AM$1=$A14,$C14,0) -> 0 | AO14: =IF($AM$1=$A14,$D14,0) -> 0 | AP14: =IF($AM$1=$A14,$E14,0) -> 0 | AQ14: =IF($AM$1=$A14,$F14,0) -> 0 | AR14: =IF($AM$1=$A14,$G14,0) -> 0 | AS14: =IF($AS$1=$A14,$B14,0) -> 0 | AT14: =IF($AS$1=$A14,$C14,0) -> 0 | AU14: =IF($AS$1=$A14,$D14,0) -> 0 | AV14: =IF($AS$1=$A14,$E14,0) -> 0 | AW14: =IF($AS$1=$A14,$F14,0) -> 0 | AX14: =IF($AS$1=$A14,$G14,0) -> 0 | AY14: =IF($AY$1=$A14,$B14,0) -> 0 | AZ14: =IF($AY$1=$A14,$C14,0) -> 0 | BA14: =IF($AY$1=$A14,$D14,0) -> 0 | BB14: =IF($AY$1=$A14,$E14,0) -> 0 | BC14: =IF($AY$1=$A14,$F14,0) -> 0 | BD14: =IF($AY$1=$A14,$G14,0) -> 0
... A19: ='Raw Rejection Data'!B20 -> Rippling | B19: =IF(ISNUMBER(SEARCH("align",'Raw Rejection Data'!$G20)),1,0) -> 0 | C19: =IF(ISNUMBER(SEARCH("*mov*",'Raw Rejection Data'!$G20)),1,0) -> 1 | D19: =IF(ISNUMBER(SEARCH("closer match",'Raw Rejection Data'!$G20)),1,0) -> 0 | E19: =IF(ISNUMBER(SEARCH("better meet",'Raw Rejection Data'!$G20)),1,0) -> 0 | F19: =IF(ISNUMBER(SEARCH("filled",'Raw Rejection Data'!$G20)),1,0) -> 0 | G19: =IF(ISNUMBER(SEARCH("*pursue other*",'Raw Rejection Data'!$G20)),1,0) -> 0 | I19: =IF($I$1=$A19,$B19,0) -> 0 | J19: =IF($I$1=$A19,$C19,0) -> 0 | K19: =IF($I$1=$A19,$D19,0) -> 0 | L19: =IF($I$1=$A19,$E19,0) -> 0 | M19: =IF($I$1=$A19,$F19,0) -> 0 | N19: =IF($I$1=$A19,$G19,0) -> 0 | O19: =IF($O$1=$A19,$B19,0) -> 0 | P19: =IF($O$1=$A19,$C19,0) -> 0 | Q19: =IF($O$1=$A19,$D19,0) -> 0 | R19: =IF($O$1=$A19,$E19,0) -> 0 | S19: =IF($O$1=$A19,$F19,0) -> 0 | T19: =IF($O$1=$A19,$G19,0) -> 0 | U19: =IF($U$1=$A19,$B19,0) -> 0 | V19: =IF($U$1=$A19,$C19,0) -> 0 | W19: =IF($U$1=$A19,$D19,0) -> 0 | X19: =IF($U$1=$A19,$E19,0) -> 0 | Y19: =IF($U$1=$A19,$F19,0) -> 0 | Z19: =IF($U$1=$A19,$G19,0) -> 0 | AA19: =IF($AA$1=$A19,$B19,0) -> 0 | AB19: =IF($AA$1=$A19,$C19,0) -> 0 | AC19: =IF($AA$1=$A19,$D19,0) -> 0 | AD19: =IF($AA$1=$A19,$E19,0) -> 0 | AE19: =IF($AA$1=$A19,$F19,0) -> 0 | AF19: =IF($AA$1=$A19,$G19,0) -> 0 | AG19: =IF($AG$1=$A19,$B19,0) -> 0 | AH19: =IF($AG$1=$A19,$C19,0) -> 0 | AI19: =IF($AG$1=$A19,$D19,0) -> 0 | AJ19: =IF($AG$1=$A19,$E19,0) -> 0 | AK19: =IF($AG$1=$A19,$F19,0) -> 0 | AL19: =IF($AG$1=$A19,$G19,0) -> 0 | AM19: =IF($AM$1=$A19,$B19,0) -> 0 | AN19: =IF($AM$1=$A19,$C19,0) -> 0 | AO19: =IF($AM$1=$A19,$D19,0) -> 0 | AP19: =IF($AM$1=$A19,$E19,0) -> 0 | AQ19: =IF($AM$1=$A19,$F19,0) -> 0 | AR19: =IF($AM$1=$A19,$G19,0) -> 0 | AS19: =IF($AS$1=$A19,$B19,0) -> 0 | AT19: =IF($AS$1=$A19,$C19,0) -> 0 | AU19: =IF($AS$1=$A19,$D19,0) -> 0 | AV19: =IF($AS$1=$A19,$E19,0) -> 0 | AW19: =IF($AS$1=$A19,$F19,0) -> 0 | AX19: =IF($AS$1=$A19,$G19,0) -> 0 | AY19: =IF($AY$1=$A19,$B19,0) -> 0 | AZ19: =IF($AY$1=$A19,$C19,0) -> 1 | BA19: =IF($AY$1=$A19,$D19,0) -> 0 | BB19: =IF($AY$1=$A19,$E19,0) -> 0 | BC19: =IF($AY$1=$A19,$F19,0) -> 0 | BD19: =IF($AY$1=$A19,$G19,0) -> 0
A21: Totals of All Systems | B21: =SUM(B3:B19) -> 4 | C21: =SUM(C3:C19) -> 10 | D21: =SUM(D3:D19) -> 1 | E21: =SUM(E3:E19) -> 1 | F21: =SUM(F3:F19) -> 2 | G21: =SUM(G3:G19) -> 3 | H21: =SUM(H3:H19) -> 0 | I21: =SUM(I3:I19) -> 3 | ... BD21: =SUM(BD3:BD19) -> 0
