Workbook

Sheet Blue KC
A2: Blue KC | D2: https://www.bluekc.com/
A4: Blue Cross/Blue Shield provider for the KC City Metro Area. Coverage Area is based on coverage in the following counties:
A6: Missouri Counties: | C6: Andrew, Atchison, Bates, Benton, Buchanan, Caldwell, Carroll, Cass, Clay, Clinton, Daviess, DeKalb, Gentry, Grundy, Harrison, Henry, Holt, Jackson, Johnson, Lafayette, Livingston, Mercer, Nodaway, Pettis, Platte, Ray, Saline, St. Clair, Vernon, Worth
A7: Kansas Counties: | C7: Johnson, Wyandotte
A9: If you know the zip code, use the scroll down box to see if it's covered. | H9: External Site for Zip Lookup:
H10: https://www.unitedstateszipcodes.org/
B11: Zip Code | C11: County | D11: State
B12: 64017 | C12: =IFERROR(VLOOKUP($B12,'Drop Down'!$A$2:$C697,2,FALSE)," ") -> Lafayette | D12: =IFERROR(VLOOKUP($B12,'Drop Down'!$A$2:$C697,3,FALSE)," ") -> MO

Sheet Blue KC Counties
A1: Missouri Counties | D1: Kansas Counties | H1: Service Area Notes
A2: Andrew | D2: Johnson
A3: Atchison | D3: Wyandotte | H3: Zip Code 51640 is based in Hamburg, IA. It serves the EXTREME tip of NW Missouri. Must use state code in combination of this zip code.
A4: Bates
A5: Benton
A6: Buchanan | O6: Missouri is denoted by the red line.
A7: Caldwell
A8: Carroll
A9: Cass
A10: Clay
A11: Clinton
A12: Daviess
A13: DeKalb
A14: Gentry
A15: Grundy
A16: Harrison
A17: Henry
A18: Holt
... A31: Worth

Sheet Kansas Zips Raw
A1: Johnson | B1: Wyandotte
A2: 66013 | B2: 66012
A3: 66018 | B3: 66101
A4: 66021 | B4: 66102
A5: 66025 | B5: 66103
A6: 66030 | B6: 66104
A7: 66206 | B7: 66105
A8: 66209 | B8: 66106
A9: 66211 | B9: 66109
A10: 66215 | B10: 66111
A11: 66219 | B11: 66112
A12: 66220 | B12: 66115
A13: 66227 | B13: 66118
... A15: 66205 | B15: 66216
A16: 66031
A17: 66061
A18: 66062
A19: 66204
A20: 66207
A21: 66210
A22: 66212
A23: 66213
A24: 66214
A25: 66221
A26: 66223
A27: 66224
... A36: 66085

Sheet Missouri Zips Raw
A1: Andrew | B1: Atchison | C1: Bates | D1: Benton | E1: Buchanan | F1: Caldwell | G1: Carroll | H1: Cass | I1: Clay | J1: Clinton | K1: Daviess | L1: DeKalb | M1: Gentry | N1: Grundy | O1: Harrison | P1: Henry | Q1: Holt | R1: Jackson | S1: Johnson | T1: Lafayette | U1: Livingston | V1: Mercer | W1: Nodaway | X1: Pettis | Y1: Platte | Z1: Ray | AA1: Saline | AB1: St. Clair | AC1: Vernon | AD1: Worth
A2: 64421 | B2: 64428 | C2: 64720 | D2: 64735 | E2: 64401 | F2: 64624 | G2: 64622 | H2: 64725 | I2: 64024 | J2: 64429 | K2: 64620 | L2: 64422 | M2: 64402 | N2: 64635 | O2: 64424 | P2: 64724 | Q2: 64437 | R2: 64014 | S2: 64011 | T2: 64001 | U2: 64624 | V2: 64632 | W2: 64423 | X2: 65325 | Y2: 64018 | Z2: 64624 | AA2: 65320 | AB2: 64724 | AC2: 64728 | AD2: 64420
A3: 64423 | B3: 64437 | C3: 64722 | D3: 65325 | E3: 64440 | F3: 64625 | G3: 64623 | H3: 64012 | I3: 64048 | J3: 64444 | K3: 64625 | L3: 64429 | M3: 64438 | N3: 64641 | O3: 64426 | P3: 64726 | Q3: 64451 | R3: 64015 | S3: 64726 | T3: 64011 | U3: 64625 | V3: 64645 | W3: 64427 | X3: 65332 | Y3: 64440 | Z3: 64017 | AA3: 65321 | AB3: 64738 | AC3: 64741 | AD3: 64441
A4: 64427 | B4: 64446 | C4: 64723 | D4: 65634 | E4: 64439 | F4: 64429 | G4: 64624 | H4: 64734 | I4: 64116 | J4: 64454 | K4: 64429 | L4: 64430 | M4: 64441 | N4: 64642 | O4: 64632 | P4: 65323 | Q4: 64466 | R4: 64016 | S4: 64019 | T4: 65321 | U4: 64601 | V4: 64661 | W4: 64428 | X4: 65333 | Y4: 64439 | Z4: 64637 | AA4: 64020 | AB4: 64740 | AC4: 64744 | AD4: 64456
A5: 64430 | B5: 51640 | C5: 64724 | D5: 65326 | E5: 64443 | F5: 64637 | G5: 64633 | H5: 64739 | I5: 64117 | J5: 64048 | K5: 64601 | L5: 64463 | M5: 64453 | N5: 64648 | O5: 64636 | P5: 64733 | Q5: 64470 | R5: 64029 | S5: 64733 | T5: 64017 | U5: 64635 | V5: 64667 | W5: 64431 | X5: 65334 | Y5: 64444 | Z5: 64024 | AA5: 65327 | AB5: 64744 | AC5: 64750 | AD5: 64458
A6: 64436 | B6: 64482 | C6: 64725 | D6: 65335 | E6: 64444 | F6: 64644 | G6: 64638 | H6: 64742 | I6: 64118 | J6: 64465 | K6: 64636 | L6: 64469 | M6: 64463 | N6: 64652 | O6: 64442 | P6: 64735 | Q6: 64473 | R6: 64030 | S6: 64020 | T6: 64020 | U6: 64638 | V6: 64672 | W6: 64432 | X6: 65335 | Y6: 64028 | Z6: 64035 | AA6: 65330 | AB6: 64750 | AC6: 64752 | AD6: 64475
A7: 64449 | B7: 64487 | C7: 64730 | D7: 65338 | E7: 64448 | F7: 64649 | G7: 64639 | H7: 64743 | I7: 64119 | J7: 64062 | K7: 64640 | L7: 64474 | M7: 64469 | N7: 64679 | O7: 64642 | P7: 64739 | Q7: 64487 | R7: 64034 | S7: 64747 | T7: 64021 | U7: 64643 | V7: 64673 | W7: 64433 | X7: 65336 | Y7: 64118 | Z7: 64036 | AA7: 65333 | AB7: 65674 | AC7: 64765 | AD7: 64486
A8: 64455 | B8: 64491 | C8: 64742 | D8: 65345 | E8: 64454 | F8: 64650 | G8: 64643 | H8: 64746 | I8: 64151 | J8: 64474 | K8: 64642 | L8: 64670 | M8: 64657 | N8: 64683 | O8: 64456 | P8: 64740 | R8: 64050 | S8: 65332 | T8: 64022 | U8: 64648 | V8: 64679 | W8: 64434 | X8: 65337 | Y8: 64151 | Z8: 64062 | AA8: 65339 | AB8: 64763 | AC8: 64767 | AD8: 64499
A9: 64457 | B9: 64496 | C9: 64745 | D9: 64776 | E9: 64484 | F9: 64465 | G9: 64035 | H9: 64747 | I9: 64155 | J9: 64477 | K9: 64644 | L9: 64490 | M9: 64471 | O9: 64458 | P9: 64761 | R9: 64052 | S9: 64037 | T9: 65327 | U9: 64656 | W9: 64445 | X9: 65340 | Y9: 64152 | Z9: 64668 | AA9: 65340 | AB9: 64770 | AC9: 64771
A10: 64459 | B10: 64498 | C10: 64752 | D10: 65735 | E10: 64501 | F10: 64062 | G10: 64668 | H10: 64034 | I10: 64156 | J10: 64490 | K10: 64647 | L10: 64494 | M10: 64475 | O10: 64467 | P10: 64770 | R10: 64053 | S10: 64040 | T10: 64037 | U10: 64664 | W10: 64455 | X10: 65345 | Y10: 64153 | Z10: 64077 | AA10: 65344 | AB10: 64776 | AC10: 64772
A11: 64463 | C11: 64770 | D11: 65078 | E11: 64503 | F11: 64671 | G11: 64682 | H11: 64701 | I11: 64157 | J11: 64492 | K11: 64648 | L11: 64497 | M11: 64670 | O11: 64657 | P11: 64788 | R11: 64054 | S11: 64061 | T11: 64067 | U11: 64683 | W11: 64457 | X11: 65347 | Y11: 64154 | Z11: 64671 | AA11: 65347 | AB11: 65735 | AC11: 64779
A12: 64480 | C12: 64779 | D12: 65355 | E12: 64504 | H12: 64040 | I12: 64158 | J12: 64493 | K12: 64649 | M12: 64479 | O12: 64471 | P12: 65360 | R12: 64055 | S12: 65336 | T12: 64071 | U12: 64686 | W12: 64461 | X12: 65348 | Y12: 64155 | Z12: 64084 | AA12: 65349 | AB12: 64780 | AC12: 64778
A13: 64483 | C13: 64780 | D13: 65779 | E13: 64505 | H13: 64147 | I13: 64161 | K13: 64654 | M13: 64489 | O13: 64670 | R13: 64056 | S13: 64761 | T13: 64074 | U13: 64688 | W13: 64468 | X13: 65301 | Y13: 64163 | Z13: 64085 | AA13: 65351 | AB13: 64781 | AC13: 64783
A14: 64505 | C14: 64788 | D14: 65360 | E14: 64506 | H14: 64061 | I14: 64165 | K14: 64657 | M14: 64499 | O14: 64481 | R14: 64057 | S14: 64070 | T14: 64075 | W14: 64475 | X14: 65350 | Y14: 64164 | AA14: 64096 | AB14: 64783 | AC14: 64784
A15: 64506 | C15: 64788 | E15: 64507 | H15: 64082 | I15: 64166 | K15: 64670 | R15: 64058 | S15: 64076 | T15: 64076 | W15: 64476 | X15: 65351 | Y15: 64079 | AB15: 65785 | AC15: 64790
A16: 64507 | E16: 64490 | H16: 64078 | I16: 64167 | K16: 64497 | R16: 64101 | S16: 64080 | T16: 64096 | W16: 64479 | X16: 65360 | Y16: 64150 | AB16: 65355
A17: 64485 | H17: 64080 | I17: 64060 | K17: 64689 | R17: 64102 | S17: 65351 | T17: 64097 | W17: 64486 | Y17: 64484 | AB17: 65774
A18: 64494 | H18: 64083 | I18: 64062 | R18: 64105 | S18: 64093 | W18: 64487 | Y18: 64089
H19: 64090 | I19: 64068 | R19: 64106 | S19: 65305 | W19: 64489 | Y19: 64492
I20: 64072 | R20: 64108 | S20: 65360 | Y20: 64092
A21: Purple Zips are in the service area, but covers mainly a service area out of scope. | I21: 64077 | R21: 64109 | Y21: 64098
I22: 64150 | R22: 64110
I23: 64089 | R23: 64111
I24: 64492 | R24: 64112
R25: 64113
R26: 64114
R27: 64120
R28: 64123
R29: 64124
R30: 64125
R31: 64126
R32: 64127
R33: 64128
R34: 64129
R35: 64130
R36: 64131
... R59: 64088

Sheet Zip Code Flat File Builder
A1: /* | B1: To use this file, export file as a CSV file. | L1: */
A2: /* | B2: Only Zip Codes are listed; add in extra parameters as needed prior to export. | L2: */
A3: Zip Code | B3: County | C3: State
A4: ='Kansas Zips Raw'!A2 -> 66013 | B4: ='Kansas Zips Raw'!$A$1 -> Johnson | C4: KS
A5: ='Kansas Zips Raw'!A3 -> 66018 | B5: ='Kansas Zips Raw'!$A$1 -> Johnson | C5: KS
A6: ='Kansas Zips Raw'!A4 -> 66021 | B6: ='Kansas Zips Raw'!$A$1 -> Johnson | C6: KS
A7: ='Kansas Zips Raw'!A5 -> 66025 | B7: ='Kansas Zips Raw'!$A$1 -> Johnson | C7: KS
A8: ='Kansas Zips Raw'!A6 -> 66030 | B8: ='Kansas Zips Raw'!$A$1 -> Johnson | C8: KS
A9: ='Kansas Zips Raw'!A7 -> 66206 | B9: ='Kansas Zips Raw'!$A$1 -> Johnson | C9: KS
A10: ='Kansas Zips Raw'!A8 -> 66209 | B10: ='Kansas Zips Raw'!$A$1 -> Johnson | C10: KS
A11: ='Kansas Zips Raw'!A9 -> 66211 | B11: ='Kansas Zips Raw'!$A$1 -> Johnson | C11: KS
A12: ='Kansas Zips Raw'!A10 -> 66215 | B12: ='Kansas Zips Raw'!$A$1 -> Johnson | C12: KS
A13: ='Kansas Zips Raw'!A11 -> 66219 | B13: ='Kansas Zips Raw'!$A$1 -> Johnson | C13: KS
A14: ='Kansas Zips Raw'!A12 -> 66220 | B14: ='Kansas Zips Raw'!$A$1 -> Johnson | C14: KS
A15: ='Kansas Zips Raw'!A13 -> 66227 | B15: ='Kansas Zips Raw'!$A$1 -> Johnson | C15: KS
... A38: ='Kansas Zips Raw'!A36 -> 66085 | B38: ='Kansas Zips Raw'!$A$1 -> Johnson | C38: KS
A39: ='Kansas Zips Raw'!B2 -> 66012 | B39: ='Kansas Zips Raw'!$B$1 -> Wyandotte | C39: KS
A40: ='Kansas Zips Raw'!B3 -> 66101 | B40: ='Kansas Zips Raw'!$B$1 -> Wyandotte | C40: KS
A41: ='Kansas Zips Raw'!B4 -> 66102 | B41: ='Kansas Zips Raw'!$B$1 -> Wyandotte | C41: KS
A42: ='Kansas Zips Raw'!B5 -> 66103 | B42: ='Kansas Zips Raw'!$B$1 -> Wyandotte | C42: KS
A43: ='Kansas Zips Raw'!B6 -> 66104 | B43: ='Kansas Zips Raw'!$B$1 -> Wyandotte | C43: KS
A44: ='Kansas Zips Raw'!B7 -> 66105 | B44: ='Kansas Zips Raw'!$B$1 -> Wyandotte | C44: KS
A45: ='Kansas Zips Raw'!B8 -> 66106 | B45: ='Kansas Zips Raw'!$B$1 -> Wyandotte | C45: KS
A46: ='Kansas Zips Raw'!B9 -> 66109 | B46: ='Kansas Zips Raw'!$B$1 -> Wyandotte | C46: KS
A47: ='Kansas Zips Raw'!B10 -> 66111 | B47: ='Kansas Zips Raw'!$B$1 -> Wyandotte | C47: KS
A48: ='Kansas Zips Raw'!B11 -> 66112 | B48: ='Kansas Zips Raw'!$B$1 -> Wyandotte | C48: KS
A49: ='Kansas Zips Raw'!B12 -> 66115 | B49: ='Kansas Zips Raw'!$B$1 -> Wyandotte | C49: KS
A50: ='Kansas Zips Raw'!B13 -> 66118 | B50: ='Kansas Zips Raw'!$B$1 -> Wyandotte | C50: KS
... A52: ='Kansas Zips Raw'!B15 -> 66216 | B52: ='Kansas Zips Raw'!$B$1 -> Wyandotte | C52: KS
A53: ='Missouri Zips Raw'!A2 -> 64421 | B53: ='Missouri Zips Raw'!A$1 -> Andrew | C53: MO
A54: ='Missouri Zips Raw'!A3 -> 64423 | B54: ='Missouri Zips Raw'!A$1 -> Andrew | C54: MO
A55: ='Missouri Zips Raw'!A4 -> 64427 | B55: ='Missouri Zips Raw'!A$1 -> Andrew | C55: MO
A56: ='Missouri Zips Raw'!A5 -> 64430 | B56: ='Missouri Zips Raw'!A$1 -> Andrew | C56: MO
A57: ='Missouri Zips Raw'!A6 -> 64436 | B57: ='Missouri Zips Raw'!A$1 -> Andrew | C57: MO
A58: ='Missouri Zips Raw'!A7 -> 64449 | B58: ='Missouri Zips Raw'!A$1 -> Andrew | C58: MO
A59: ='Missouri Zips Raw'!A8 -> 64455 | B59: ='Missouri Zips Raw'!A$1 -> Andrew | C59: MO
A60: ='Missouri Zips Raw'!A9 -> 64457 | B60: ='Missouri Zips Raw'!A$1 -> Andrew | C60: MO
A61: ='Missouri Zips Raw'!A10 -> 64459 | B61: ='Missouri Zips Raw'!A$1 -> Andrew | C61: MO
A62: ='Missouri Zips Raw'!A11 -> 64463 | B62: ='Missouri Zips Raw'!A$1 -> Andrew | C62: MO
A63: ='Missouri Zips Raw'!A12 -> 64480 | B63: ='Missouri Zips Raw'!A$1 -> Andrew | C63: MO
...

Sheet Drop Down
A1: Zip Code | B1: County | C1: State
A2: ----- | B2: ----- | C2: -----
A3: ='Missouri Zips Raw'!B5 -> 51640 | B3: ='Missouri Zips Raw'!B$1 -> Atchison | C3: MO
A4: ='Missouri Zips Raw'!T2 -> 64001 | B4: ='Missouri Zips Raw'!T$1 -> Lafayette | C4: MO
A5: ='Missouri Zips Raw'!S2 -> 64011 | B5: ='Missouri Zips Raw'!S$1 -> Johnson | C5: MO
A6: ='Missouri Zips Raw'!T3 -> 64011 | B6: ='Missouri Zips Raw'!T$1 -> Lafayette | C6: MO
A7: ='Missouri Zips Raw'!H3 -> 64012 | B7: ='Missouri Zips Raw'!H$1 -> Cass | C7: MO
A8: ='Missouri Zips Raw'!R2 -> 64014 | B8: ='Missouri Zips Raw'!R$1 -> Jackson | C8: MO
A9: ='Missouri Zips Raw'!R3 -> 64015 | B9: ='Missouri Zips Raw'!R$1 -> Jackson | C9: MO
A10: ='Missouri Zips Raw'!R4 -> 64016 | B10: ='Missouri Zips Raw'!R$1 -> Jackson | C10: MO
A11: ='Missouri Zips Raw'!T5 -> 64017 | B11: ='Missouri Zips Raw'!T$1 -> Lafayette | C11: MO
A12: ='Missouri Zips Raw'!Z3 -> 64017 | B12: ='Missouri Zips Raw'!Z$1 -> Ray | C12: MO
A13: ='Missouri Zips Raw'!Y2 -> 64018 | B13: ='Missouri Zips Raw'!Y$1 -> Platte | C13: MO
A14: ='Missouri Zips Raw'!S4 -> 64019 | B14: ='Missouri Zips Raw'!S$1 -> Johnson | C14: MO
A15: ='Missouri Zips Raw'!S6 -> 64020 | B15: ='Missouri Zips Raw'!S$1 -> Johnson | C15: MO
A16: ='Missouri Zips Raw'!T6 -> 64020 | B16: ='Missouri Zips Raw'!T$1 -> Lafayette | C16: MO
A17: ='Missouri Zips Raw'!AA4 -> 64020 | B17: ='Missouri Zips Raw'!AA$1 -> Saline | C17: MO
A18: ='Missouri Zips Raw'!T7 -> 64021 | B18: ='Missouri Zips Raw'!T$1 -> Lafayette | C18: MO
A19: ='Missouri Zips Raw'!T8 -> 64022 | B19: ='Missouri Zips Raw'!T$1 -> Lafayette | C19: MO
A20: ='Missouri Zips Raw'!I2 -> 64024 | B20: ='Missouri Zips Raw'!I$1 -> Clay | C20: MO
A21: ='Missouri Zips Raw'!Z5 -> 64024 | B21: ='Missouri Zips Raw'!Z$1 -> Ray | C21: MO
A22: ='Missouri Zips Raw'!Y6 -> 64028 | B22: ='Missouri Zips Raw'!Y$1 -> Platte | C22: MO
A23: ='Missouri Zips Raw'!R5 -> 64029 | B23: ='Missouri Zips Raw'!R$1 -> Jackson | C23: MO
A24: ='Missouri Zips Raw'!R6 -> 64030 | B24: ='Missouri Zips Raw'!R$1 -> Jackson | C24: MO
A25: ='Missouri Zips Raw'!H10 -> 64034 | B25: ='Missouri Zips Raw'!H$1 -> Cass | C25: MO
A26: ='Missouri Zips Raw'!R7 -> 64034 | B26: ='Missouri Zips Raw'!R$1 -> Jackson | C26: MO
A27: ='Missouri Zips Raw'!G9 -> 64035 | B27: ='Missouri Zips Raw'!G$1 -> Carroll | C27: MO
A28: ='Missouri Zips Raw'!Z6 -> 64035 | B28: ='Missouri Zips Raw'!Z$1 -> Ray | C28: MO
A29: ='Missouri Zips Raw'!Z7 -> 64036 | B29: ='Missouri Zips Raw'!Z$1 -> Ray | C29: MO
A30: ='Missouri Zips Raw'!S9 -> 64037 | B30: ='Missouri Zips Raw'!S$1 -> Johnson | C30: MO
A31: ='Missouri Zips Raw'!T10 -> 64037 | B31: ='Missouri Zips Raw'!T$1 -> Lafayette | C31: MO
A32: ='Missouri Zips Raw'!H12 -> 64040 | B32: ='Missouri Zips Raw'!H$1 -> Cass | C32: MO
A33: ='Missouri Zips Raw'!S10 -> 64040 | B33: ='Missouri Zips Raw'!S$1 -> Johnson | C33: MO
A34: ='Missouri Zips Raw'!I3 -> 64048 | B34: ='Missouri Zips Raw'!I$1 -> Clay | C34: MO
A35: ='Missouri Zips Raw'!J5 -> 64048 | B35: ='Missouri Zips Raw'!J$1 -> Clinton | C35: MO
A36: ='Missouri Zips Raw'!R8 -> 64050 | B36: ='Missouri Zips Raw'!R$1 -> Jackson | C36: MO
A37: ='Missouri Zips Raw'!R9 -> 64052 | B37: ='Missouri Zips Raw'!R$1 -> Jackson | C37: MO
A38: ='Missouri Zips Raw'!R10 -> 64053 | B38: ='Missouri Zips Raw'!R$1 -> Jackson | C38: MO
A39: ='Missouri Zips Raw'!R11 -> 64054 | B39: ='Missouri Zips Raw'!R$1 -> Jackson | C39: MO
A40: ='Missouri Zips Raw'!R12 -> 64055 | B40: ='Missouri Zips Raw'!R$1 -> Jackson | C40: MO
...
